<?xml version="1.0"?>

<!-- 
  The cube has side length 7cm.
  The cube is connected to world with a planar joint.
  (https://github.com/pangtao22/quasistatic_simulator)
-->

<sdf version="1.7">
  <model name="hinge_box">

    <joint name="world_box_offset" type="fixed">
      <child>box_root</child>
      <parent>world</parent>
      <axis>
        <limit>
          <effort>0</effort>
        </limit>
      </axis>
    </joint>

    <link name="box_root">
        <pose relative_to="__model__">0.0 0.0 0.0 0.0 0 0</pose>
        <visual name="visual">
            <pose>0.07 0.0 0.1 0.0 0 0</pose>
            <geometry>
            <box>
                <size> 0.3 0.3 0.04 </size>
            </box>
            </geometry>
            <material>
            <diffuse>0.5 0.5 0.1 0.8</diffuse>
            </material>
        </visual>
    </link>

    <joint name="box_root_joint" type="revolute">
        <child>box_link</child>
        <parent>box_root</parent>
        <axis>
          <xyz>0 1 0</xyz>
          <limit>
            <effort>0</effort>
            <lower>-1.5708</lower>
            <upper>0.0</upper>
          </limit>
        </axis>
    </joint>

    <!-- <link name="box_base">
        <pose relative_to="__model__">-0.06 -0.25 0.103 0 0 0</pose>
        <collision name="collision">
            <geometry>
            <box>
                <size> 0.05 0.05 0.02 </size>
            </box>
            </geometry>
        </collision>
        <visual name="visual">
            <geometry>
            <box>
                <size> 0.05 0.05 0.02 </size>
            </box>
            </geometry>
            <material>
            <diffuse>0.1 0.5 0.5 0.8</diffuse>
            </material>
        </visual>
    </link> -->

    <link name="box_link">
        <pose relative_to="box_root">0.20 0.0 0.1 0.0 0 0</pose>
        <collision name="collision">
            <pose>-0.13 0 0 0 0 0</pose>
            <geometry>
            <box>
                <size> 0.3 0.3 0.04 </size>
            </box>
            </geometry>
        </collision>
        <visual name="visual">
            <pose>-0.13 0 0 0 0 0</pose>
            <geometry>
            <box>
                <size> 0.3 0.3 0.04 </size>
            </box>
            </geometry>
            <material>
            <diffuse>0.1 0.5 0.5 0.8</diffuse>
            </material>
        </visual>
    </link>

  </model>
</sdf>
