<?xml version="1.0"?>

<!-- 
  This file contains a valve of radius=0.03m.
  The valve is a manipuland for demonstration with allegro hand.
  Note: the valve rotate only around the z-axis, with fixed x
  and y value compatible with the allegro_hand_right model in
  the repository quasistatic_simulator
  (https://github.com/pangtao22/quasistatic_simulator)
-->

<sdf version="1.7">
  <model name="valve_r0.03m">

    <joint name="world_valve_offset" type="fixed">
      <child>valve_root</child>
      <parent>world</parent>
      <axis>
        <limit>
          <effort>0</effort>
        </limit>
      </axis>
    </joint>

    <link name="valve_root">
      <!-- For sphere collision -->
      <pose relative_to="__model__">-0.08 0.0 0.11 0.0 0 0</pose>
      <!-- For cuboid collisions -->
      <!-- <pose relative_to="__model__">-0.08 0.0 0.13 1.5708 0 0</pose> -->
    </link>

    <joint name="valve_root_joint" type="revolute">
        <child>valve_link</child>
        <parent>valve_root</parent>
        <axis>
          <xyz>0 0 1</xyz>
          <limit>
            <effort>0</effort>
          </limit>
          <!-- <dynamics>
            <damping>1.5e-2</damping>
          </dynamics> -->
        </axis>
    </joint>

    <link name="valve_link">
      <pose relative_to="valve_root">0 0 0 0 0 0</pose>
      <inertial>
        <mass>1.0</mass>
        <inertia>
          <ixx>0.001</ixx>
          <ixy>0</ixy>
          <ixz>0</ixz>
          <iyy>0.001</iyy>
          <iyz>0</iyz>
          <izz>0.001</izz>
        </inertia>
      </inertial>

      <visual name="visual">
        <pose relative_to="valve_root">0 0 0 1.5708 0 0</pose>
        <geometry>
          <capsule>
            <radius>0.02</radius>
            <length>0.16</length>
          </capsule>
        </geometry>
        <material>
          <diffuse>0.1 0.5 0.5 0.8</diffuse>
        </material>
      </visual>

      <!-- 
        In Drake, SignedDistance operation is not supported for sphere and cylinder.
        Therefore, we use six spheres to approximate the capsule.
       -->

      <!-- <collision name="collision_0">
        <pose> 0 0 0.02 0 0 0 </pose>
        <geometry>
          <sphere>
            <radius>0.02</radius>
          </sphere>
        </geometry>
        <surface>
          <friction>
            <ode>
              <mu>1.0</mu>
              <mu2>1.0</mu2>
            </ode>
          </friction>
        </surface>
      </collision>

      <collision name="collision_1">
        <pose> 0 0 -0.02 0 0 0 </pose>
        <geometry>
          <sphere>
            <radius>0.02</radius>
          </sphere>
        </geometry>
        <surface>
          <friction>
            <ode>
              <mu>1.0</mu>
              <mu2>1.0</mu2>
            </ode>
          </friction>
        </surface>
      </collision>

      <collision name="collision_2">
        <pose> 0 0 0.06 0 0 0 </pose>
        <geometry>
          <sphere>
            <radius>0.02</radius>
          </sphere>
        </geometry>
        <surface>
          <friction>
            <ode>
              <mu>1.0</mu>
              <mu2>1.0</mu2>
            </ode>
          </friction>
        </surface>
      </collision>

      <collision name="collision_3">
        <pose> 0 0 -0.06 0 0 0 </pose>
        <geometry>
          <sphere>
            <radius>0.02</radius>
          </sphere>
        </geometry>
        <surface>
          <friction>
            <ode>
              <mu>1.0</mu>
              <mu2>1.0</mu2>
            </ode>
          </friction>
        </surface>
      </collision>

      <collision name="collision_4">
        <pose> 0 0 0.1 0 0 0 </pose>
        <geometry>
          <sphere>
            <radius>0.02</radius>
          </sphere>
        </geometry>
        <surface>
          <friction>
            <ode>
              <mu>1.0</mu>
              <mu2>1.0</mu2>
            </ode>
          </friction>
        </surface>
      </collision>

      <collision name="collision_5">
        <pose> 0 0 -0.1 0 0 0 </pose>
        <geometry>
          <sphere>
            <radius>0.02</radius>
          </sphere>
        </geometry>
        <surface>
          <friction>
            <ode>
              <mu>1.0</mu>
              <mu2>1.0</mu2>
            </ode>
          </friction>
        </surface>
      </collision> -->

      <collision name="collision">
        <pose> 0 0 0 0 0 0 </pose>
        <geometry>
          <box>
            <size> 0.04 0.20 0.04 </size>
          </box>
        </geometry>
        <surface>
          <friction>
            <ode>
              <mu>1.0</mu>
              <mu2>1.0</mu2>
            </ode>
          </friction>
        </surface>
      </collision>

      <visual name="collision_vis">
        <pose> 0 0 0 0 0 0 </pose>
        <geometry>
          <box>
            <size> 0.04 0.20 0.04 </size>
          </box>
        </geometry>
        <material>
          <diffuse>0.8 0.2 0.2 0.4</diffuse>
        </material>
      </visual>

    </link>

  </model>
</sdf>
