<!-- 
    This MJCF scene is used for our method
    allegro_aligned_mujoco.xml (with partially diabled thumb collision geometry) is used
 -->

<mujoco model="my_scene">
    <!-- Include the Leap Hand model -->
    <include file="./allegro_aligned_mujoco.xml"/>

    <statistic center="0 0 0.1" extent=".3"/>

    <!-- Define the world body -->
    <worldbody>
        <!-- Define the manipulated object, e.g., a ball -->
        <body name="object" pos="-0.035 0.0 0.072" euler="0 0 3.1415927" >
            <inertial pos="0 0 0" mass="0.1" diaginertia="0.000144 0.000144 0.000144" />
            <geom name="object_geom" type="sphere" size="0.06" rgba="0.1 0.5 0.5 0.8" condim="6" priority="1" friction="2.0 0.002 0.002" />
            <geom type="cylinder" pos="0.0 0.0 0.0325" size="0.005 0.035" rgba="0.0 0.0 1.0 1.0" class="visual" />
            <geom type="cylinder" pos="0.0 0.0325 0.0" euler="1.5708 0.0 0.0" size="0.005 0.035" rgba="0.0 1.0 0.0 1.0" class="visual" />
            <geom type="cylinder" pos="0.0325 0.0 0.0" euler="0.0 1.5708 0.0" size="0.005 0.035" rgba="1.0 0.0 0.0 1.0" class="visual" />
            <joint type="ball" axis="0 0 1" damping="0.1" />
        </body>
    </worldbody>

    <!-- Define actuators, sensors, or additional elements here -->
</mujoco>
